Workbook
Name Years: '[1]Value Summary'!$A$3:$A$17

Sheet Updated Multi-Year Budget
A1: Laugh CRA
A2: Multi-Year Project Area Budget Projections
A3: #VALUE!
C6: HISTORIC | D6: PROJECTED ========>
C7: Year 1 | D7: Year 2 | E7: Year 3 | F7: Year 4 | G7: Year 5 | H7: Year 6 | I7: Year 7 | J7: Year 8 | K7: Year 9 | L7: Year 10 | M7: Year 11 | N7: Year 12 | O7: Year 13 | P7: Year 14 | Q7: Year 15 | R7: Year 16 | S7: Year 17 | T7: Year 18 | U7: Year 19 | V7: Year 20 | X7: PER Shannon Wimmer, DO NOT INCLUDE TY2023/FY2024 or TY2022/FY2023. In dispute with County over whether or not they get this. Mayor decided to just not include this year. 10/30/2020.
A8: Tax Year | B8: 2023 | C8: 2024 | D8: 2025 | E8: 2026 | F8: 2027 | G8: 2028 | H8: 2029 | I8: 2030 | J8: 2031 | K8: 2032 | L8: 2033 | M8: 2034 | N8: 2035 | O8: 2036 | P8: 2037 | Q8: 2038 | R8: 2039 | S8: 2040 | T8: 2041 | U8: 2042 | V8: 2044
A9: Payment Year | B9: 2024 | C9: 2025 | D9: 2026 | E9: 2027 | F9: 2028 | G9: 2029 | H9: 2030 | I9: 2031 | J9: 2032 | K9: 2033 | L9: 2034 | M9: 2035 | N9: 2036 | O9: 2037 | P9: 2038 | Q9: 2039 | R9: 2040 | S9: 2041 | T9: 2042 | U9: 2043 | V9: 2045 | W9: TOTALS
A11: REVENUE: | AB11: 1226
A12: REVENUES
A13: TAXABLE VALUATION: | AA13: =AB13/$AB$11 -> 0.71288744 | AB13: 874 | AC13: Developed
A14: Real Property | B14: 52500000 | C14: 52500000 | D14: =C69 -> 19825000 | E14: =D14*(1+D70) -> 27450000 | F14: =E14*(1+E70) -> 27450000 | G14: =F14*(1+F70) -> 35075000 | H14: =G14*(1+G70) -> 35075000 | I14: =H14*(1+H70) -> 35075000 | J14: =I14*(1+I70) -> 35075000 | K14: =J14*(1+J70) -> 35075000 | L14: =K14*(1+K70) -> 35075000 | ... V14: =U14*(1+U70) -> 35075000 | AA14: =AB14/$AB$11 -> 0.28711256 | AB14: 352 | AC14: Undeveloped
A15: Personal Property | B15: 0 | C15: 0 | D15: 0 | E15: 0 | F15: 0 | G15: 0 | H15: 0 | I15: 0 | J15: 0 | K15: 0 | L15: 0 | M15: 0 | N15: 0 | O15: 0 | P15: 0 | Q15: 0 | R15: 0 | S15: 0 | T15: 0 | U15: 0 | V15: 0
A16: Centrally Assessed | B16: 10000000 | C16: 10000000 | D16: 10000000 | E16: 10000000 | F16: 10000000 | G16: 10000000 | H16: 10000000 | I16: 10000000 | J16: 10000000 | K16: 10000000 | L16: 10000000 | M16: 10000000 | N16: 10000000 | O16: 10000000 | P16: 10000000 | Q16: 10000000 | R16: 10000000 | S16: 10000000 | T16: 10000000 | U16: 10000000 | V16: 10000000
A17: Total Assessed Value | C17: =SUM(C14:C16) -> 12644832 | D17: =SUM(D14:D16) -> 19963117 | E17: =SUM(E14:E16) -> 27588117 | F17: =SUM(F14:F16) -> 27588117 | G17: =SUM(G14:G16) -> 35213117 | H17: =SUM(H14:H16) -> 35213117 | I17: =SUM(I14:I16) -> 35213117 | J17: =SUM(J14:J16) -> 35213117 | ... V17: =SUM(V14:V16) -> 35213117
A18: Base Year Value
A19: Real Property | B19: 5000000 | C19: =S19 -> 0
A20: Personal Property | C20: 0
A21: Centrally Assessed | C21: =S21 -> 0
A22: Base Year Value | B22: 5000000 | C22: 0 | D22: 0 | E22: 0 | F22: 0 | G22: 0 | H22: 0 | I22: 0 | J22: 0 | K22: 0 | L22: 0 | M22: 0 | N22: 0 | O22: 0 | P22: 0 | Q22: 0 | R22: 0
A23: Total Incremental Assessed Value | C23: =C17-C22 -> 12644832 | D23: =D17-D22 -> 19963117 | E23: =E17-E22 -> 27588117 | F23: =F17-F22 -> 27588117 | G23: =G17-G22 -> 35213117 | H23: =H17-H22 -> 35213117 | I23: =I17-I22 -> 35213117 | J23: =J17-J22 -> 35213117 | ... V23: =V17-V22 -> 35213117
A25: TAX RATES
A26: 1010_BEAVER | D26: 0.001519
A27: 1010_BOX ELDER | D27: 0.001218
A28: 1010_CACHE | D28: 0.001124
A29: 1010_CARBON | D29: 0.002495
A30: 1010_DAVIS | D30: 0.001034
A31: 1010_EMERY COUNTY | D31: 0.004283
A32: 1010_IRON | D32: 0.000794
A33: 1010_JUAB | D33: 0.001947
A34: 1010_KANE | D34: 0.002006
A35: 1010_MORGAN | D35: 0.001727
W36: =SUM(U36:U36) -> 0
A37: PARTICIPATION PERCENTAGES
A38: Tooele County | C38: 0.75 | D38: =C38 -> 0.75 | E38: =D38 -> 0.75 | F38: =E38 -> 0.75 | G38: =F38 -> 0.75 | H38: =G38 -> 0.75 | I38: =H38 -> 0.75 | J38: =I38 -> 0.75 | K38: =J38 -> 0.75 | ... V38: =U38 -> 0.75
A39: Tooele County School District | C39: 0.5 | D39: =C39 -> 0.5 | E39: =D39 -> 0.5 | F39: =E39 -> 0.5 | G39: =F39 -> 0.5 | H39: =G39 -> 0.5 | I39: =H39 -> 0.5 | J39: =I39 -> 0.5 | K39: =J39 -> 0.5 | ... V39: =U39 -> 0.5
A40: Tooele City | C40: 0.75 | D40: =C40 -> 0.75 | E40: =D40 -> 0.75 | F40: =E40 -> 0.75 | G40: =F40 -> 0.75 | H40: =G40 -> 0.75 | I40: =H40 -> 0.75 | J40: =I40 -> 0.75 | K40: =J40 -> 0.75 | ... V40: =U40 -> 0.75
A42: PROJECT PORTION
A43: Tooele County | C43: =C38*C32 -> 11901.948 | D43: =D38*D32 -> 14238.693 | E43: =E38*E32 -> 19677.224 | F43: =F38*F32 -> 19677.224 | G43: =G38*G32 -> 25115.756 | H43: =H38*H32 -> 25115.756 | I43: =I38*I32 -> 25115.756 | J43: =J38*J32 -> 25115.756 | ... V43: =V38*V32 -> 25115.756 | W43: =SUM(C43:V43) -> 467347.18 | X43: Total Capped Amount of $900,000
A44: Tooele County School District | C44: =C39*C33 -> 56610.913 | D44: =D39*D33 -> 66656.848 | E44: =E39*E33 -> 92116.723 | F44: =F39*F33 -> 92116.723 | G44: =G39*G33 -> 117576.6 | H44: =H39*H33 -> 117576.6 | I44: =I39*I33 -> 117576.6 | J44: =J39*J33 -> 117576.6 | ... V44: =V39*V33 -> 117576.6 | W44: =SUM(C44:V44) -> 2188726.8 | X44: Total Capped Amount of $2,500,000
A45: Tooele City | C45: =C34*C40 -> 24221.176 | D45: =D34*D40 -> 34451.349 | E45: =E34*E40 -> 47610.193 | F45: =F34*F40 -> 47610.193 | G45: =G34*G40 -> 60769.037 | H45: =H34*H40 -> 60769.037 | I45: =I34*I40 -> 60769.037 | J45: =J34*J40 -> 60769.037 | ... V45: =V34*V40 -> 60769.037 | W45: =SUM(C45:V45) -> 1126197.5 | X45: Total Capped Amount of $2,000,000
...

Sheet Sheet1
C6: GROWTH IN ASSESSED VALUE | E6: CURRENT YEAR | F6: COMPARISON YEAR | G6: GROWTH RATE | H6: CAGR
C8: ASSESSED VALUES IN PROJECT AREA
C9: Annual Growth in Project Area (2024 vs. 2023) | E9: ='Updated Multi-Year Budget'!C23 -> 12644832 | F9: N/A | G9: N/A | H9: N/A
C10: Life Growth in Project Area (2024 vs. Base) | E10: =E9 -> 12644832 | F10: =F9 -> N/A | G10: =G9 -> N/A | H10: =H9 -> N/A
C17: GROWTH IN TAX INCREMENT | E17: ORIGINAL BUDGET* REVENUES | F17: ACTUAL REVENUE | G17: BASE YEAR VALUE REVENUES | H17: %
H18: ABOVE
H19: BASE
C20: TAX INCREMENT FROM PROJECT AREA
C21: Tax Year 2024 | E21: 15691.616 | F21: =#REF! -> #REF! | G21: =($C$14*-1)*#REF! -> #REF! | H21: =(F21-G21)/G21 -> #REF!
C22: Lifetime Revenue (2017-2026) | E22: =#REF! -> #REF! | F22: =SUM(#REF!) -> #REF! | G22: =#REF! -> #REF! | H22: =(F22-G22)/G22 -> #REF!
C23: PASS THROUGH INCREMENT (ABOVE BASE)
C24: Tax Year 2024 | E24: =E21 -> 15691.616 | F24: =F21 -> #REF! | G24: =G21 -> #REF! | H24: =(F24-G24)/G24 -> #REF!
C25: Lifetime Revenue (2017-2026) | E25: =E22 -> #REF! | F25: =F22 -> #REF! | G25: =G22 -> #REF! | H25: =(F25-G25)/G25 -> #REF!
C29: PROJECT AREA BUDGET | D29: FY 2025-2045
C30: REVENUES | D30: TOTALS | E30: Totals
C31: Property Tax Increment | D31: =SUM(#REF!) -> #REF! | E31: =SUM('Updated Multi-Year Budget'!C51:V51) -> 6032271.4
C32: Total Revenue | D32: =SUM(D31) -> #REF! | E32: =SUM(E31) -> 6032271.4
C33: EXPENDITURES | D33: TOTALS | E33: Totals
C34: CRA Administration @ 5% | D34: =SUM(#REF!) -> #REF! | E34: =SUM('Updated Multi-Year Budget'!C57:V57) -> 189113.57
C35: Guaranteed Developer Payment | D35: =SUM(#REF!)-1 -> #REF! | E35: =SUM('Updated Multi-Year Budget'!C59:V59) -> 2250000
C36: Developer Reimbursment | E36: =SUM('Updated Multi-Year Budget'!C60:V60) -> 3593157.9
C37: Total Expenditures | D37: =SUM(D34:D35) -> #REF! | E37: =SUM(E34:E36) -> 6032271.4

Sheet Annual Budget
A1: 1000 North Retail Community Reinvestment Area | H1: 1000 North Retail Community Reinvestment Area | L1: 1000 North Retail Community Reinvestment Area
A2: =C6&" Annual Budget" -> 2025 Annual Budget | H2: =J6&" Annual Budget" -> 2026 Annual Budget | L2: =N6&" Annual Budget" -> 2027 Annual Budget
A3: #VALUE! | H3: #VALUE! | L3: #VALUE!
B4: Year | C4: =LOOKUP(C5,'Updated Multi-Year Budget'!C8:V8,'Updated Multi-Year Budget'!C73:V73) -> 1 | I4: Year | J4: 2 | M4: Year | N4: 3
B5: Tax Year | C5: 2024 | I5: Tax Year | J5: 2025 | M5: Tax Year | N5: 2026
B6: Payment Year | C6: =LOOKUP(C5,'Updated Multi-Year Budget'!C8:V8,'Updated Multi-Year Budget'!C9:V9) -> 2025 | I6: Payment Year | J6: 2026 | M6: Payment Year | N6: 2027
A7: REVENUES | H7: REVENUES | L7: REVENUES
A8: TAXABLE VALUATION: | H8: TAXABLE VALUATION: | L8: TAXABLE VALUATION:
A9: Real Property | C9: ='Updated Multi-Year Budget'!C14 -> 12506715 | H9: Real Property | J9: ='Updated Multi-Year Budget'!D14 -> 19825000 | L9: Real Property | N9: ='Updated Multi-Year Budget'!E14 -> 27450000
A10: Personal Property | C10: =LOOKUP($C$5,'Updated Multi-Year Budget'!$C$8:$V$8,'Updated Multi-Year Budget'!C15:V15) -> 0 | H10: Personal Property | J10: =LOOKUP($C$5,'Updated Multi-Year Budget'!$C$8:$V$8,'Updated Multi-Year Budget'!J15:AC15) -> 0 | L10: Personal Property | N10: =LOOKUP($C$5,'Updated Multi-Year Budget'!$C$8:$V$8,'Updated Multi-Year Budget'!N15:AG15) -> 0
A11: Centrally Assessed | C11: ='Updated Multi-Year Budget'!C16 -> 138117 | H11: Centrally Assessed | J11: ='Updated Multi-Year Budget'!C16 -> 138117 | L11: Centrally Assessed | N11: ='Updated Multi-Year Budget'!E16 -> 138117
A12: Total Assessed Value | C12: =LOOKUP($C$5,'Updated Multi-Year Budget'!$C$8:$V$8,'Updated Multi-Year Budget'!C17:V17) -> 12644832 | H12: Total Assessed Value | J12: =SUM(J9:J11) -> 19963117 | L12: Total Assessed Value | N12: =SUM(N9:N11) -> 27588117
A13: Base Year Value | C13: =LOOKUP($C$5,'Updated Multi-Year Budget'!$C$8:$V$8,'Updated Multi-Year Budget'!C22:V22) -> 0 | H13: Base Year Value | J13: =LOOKUP($C$5,'Updated Multi-Year Budget'!$C$8:$V$8,'Updated Multi-Year Budget'!J22:AC22) -> 0 | L13: Base Year Value | N13: =LOOKUP($C$5,'Updated Multi-Year Budget'!$C$8:$V$8,'Updated Multi-Year Budget'!N22:AG22) -> 0
A14: Total Incremental Assessed Value | C14: =C12-C13 -> 12644832 | H14: Total Incremental Assessed Value | J14: =J12-J13 -> 19963117 | L14: Total Incremental Assessed Value | N14: =N12-N13 -> 27588117
A15: TAX RATES | C15: Real & Centrally Assessed | H15: TAX RATES | J15: Real & Centrally Assessed | L15: TAX RATES | N15: Real & Centrally Assessed
A16: ='Updated Multi-Year Budget'!A26 -> Tooele County | C16: =LOOKUP($C$5,'Updated Multi-Year Budget'!$C$8:$V$8,'Updated Multi-Year Budget'!C26:V26) -> 0.001255 | H16: Tooele County | J16: =LOOKUP($C$5,'Updated Multi-Year Budget'!$C$8:$V$8,'Updated Multi-Year Budget'!J26:AC26) -> 0.000951 | L16: Tooele County | N16: =LOOKUP($C$5,'Updated Multi-Year Budget'!$C$8:$V$8,'Updated Multi-Year Budget'!N26:AG26) -> 0.000951
A17: ='Updated Multi-Year Budget'!A27 -> Tooele County School District | C17: =LOOKUP($C$5,'Updated Multi-Year Budget'!$C$8:$V$8,'Updated Multi-Year Budget'!C27:V27) -> 0.008954 | H17: Tooele County School District | J17: =LOOKUP($C$5,'Updated Multi-Year Budget'!$C$8:$V$8,'Updated Multi-Year Budget'!J27:AC27) -> 0.006678 | L17: Tooele County School District | N17: =LOOKUP($C$5,'Updated Multi-Year Budget'!$C$8:$V$8,'Updated Multi-Year Budget'!N27:AG27) -> 0.006678
A18: ='Updated Multi-Year Budget'!A28 -> Tooele City | C18: =LOOKUP($C$5,'Updated Multi-Year Budget'!$C$8:$V$8,'Updated Multi-Year Budget'!C28:V28) -> 0.002554 | H18: Tooele City | J18: =LOOKUP($C$5,'Updated Multi-Year Budget'!$C$8:$V$8,'Updated Multi-Year Budget'!J28:AC28) -> 0.002301 | L18: Tooele City | N18: =LOOKUP($C$5,'Updated Multi-Year Budget'!$C$8:$V$8,'Updated Multi-Year Budget'!N28:AG28) -> 0.002301
A19: Total Tax Rate | C19: =C16+C18+C17 -> 0.012763 | H19: Total Tax Rate | J19: =J16+J18+J17 -> 0.00993 | L19: Total Tax Rate | N19: =N16+N18+N17 -> 0.00993
A20: PROPERTY TAX INCREMENT REVENUES | H20: PROPERTY TAX INCREMENT REVENUES | L20: PROPERTY TAX INCREMENT REVENUES
A21: =A16 -> Tooele County | C21: ='Updated Multi-Year Budget'!C32 -> 15869.264 | H21: Tooele County | J21: ='Updated Multi-Year Budget'!D32 -> 18984.924 | L21: Tooele County | N21: ='Updated Multi-Year Budget'!E32 -> 26236.299
A22: =A17 -> Tooele County School District | C22: ='Updated Multi-Year Budget'!C33 -> 113221.83 | H22: Tooele County School District | J22: ='Updated Multi-Year Budget'!D33 -> 133313.7 | L22: Tooele County School District | N22: ='Updated Multi-Year Budget'!E33 -> 184233.45
A23: =A18 -> Tooele City | C23: ='Updated Multi-Year Budget'!C34 -> 32294.901 | H23: Tooele City | J23: ='Updated Multi-Year Budget'!D34 -> 45935.132 | L23: Tooele City | N23: ='Updated Multi-Year Budget'!E34 -> 63480.257
A24: Total Property Tax Increment | C24: =LOOKUP($C$5,'Updated Multi-Year Budget'!$C$8:$V$8,'Updated Multi-Year Budget'!C35:V35) -> 161385.99 | H24: Total Property Tax Increment | J24: =SUM(J21:J23) -> 198233.75 | L24: Total Property Tax Increment | N24: =SUM(N21:N23) -> 273950
A25: PARTICIPATION PERCENTAGES | H25: PARTICIPATION PERCENTAGES | L25: PARTICIPATION PERCENTAGES
A26: Tooele County | C26: ='Updated Multi-Year Budget'!C38 -> 0.75 | H26: Tooele County | J26: ='Updated Multi-Year Budget'!J38 -> 0.75 | L26: Tooele County | N26: ='Updated Multi-Year Budget'!N38 -> 0.75
A27: Tooele County School District | C27: ='Updated Multi-Year Budget'!C39 -> 0.5 | H27: Tooele County School District | J27: ='Updated Multi-Year Budget'!J39 -> 0.5 | L27: Tooele County School District | N27: ='Updated Multi-Year Budget'!N39 -> 0.5
A28: Tooele City | C28: ='Updated Multi-Year Budget'!C40 -> 0.75 | H28: Tooele City | J28: ='Updated Multi-Year Budget'!J40 -> 0.75 | L28: Tooele City | N28: ='Updated Multi-Year Budget'!N40 -> 0.75
A30: PROJECT PORTION | H30: PROJECT PORTION | L30: PROJECT PORTION
A31: =A21 -> Tooele County | C31: ='Updated Multi-Year Budget'!C43 -> 11901.948 | H31: =H21 -> Tooele County | J31: ='Updated Multi-Year Budget'!C43 -> 11901.948 | L31: =L21 -> Tooele County | N31: ='Updated Multi-Year Budget'!E43 -> 19677.224
A32: =A22 -> Tooele County School District | C32: ='Updated Multi-Year Budget'!C44 -> 56610.913 | H32: =H22 -> Tooele County School District | J32: ='Updated Multi-Year Budget'!C44 -> 56610.913 | L32: =L22 -> Tooele County School District | N32: ='Updated Multi-Year Budget'!E44 -> 92116.723
A33: =A23 -> Tooele City | C33: ='Updated Multi-Year Budget'!C45 -> 24221.176 | H33: =H23 -> Tooele City | J33: ='Updated Multi-Year Budget'!C45 -> 24221.176 | L33: =L23 -> Tooele City | N33: ='Updated Multi-Year Budget'!E45 -> 47610.193
A34: Total Property Tax Increment Revenue to Project Area | C34: =SUM(C31:C33) -> 92734.037 | H34: Total Property Tax Increment Revenue to Project Area | J34: =SUM(J31:J33) -> 92734.037 | L34: Total Property Tax Increment Revenue to Project Area | N34: =SUM(N31:N33) -> 159404.14
A35: ='Updated Multi-Year Budget'!A47 -> Interest Revenues Earned | C35: =LOOKUP($C$5,'Updated Multi-Year Budget'!$C$8:$V$8,'Updated Multi-Year Budget'!C47:V47) -> 0 | H35: Interest Revenues Earned | J35: =LOOKUP($C$5,'Updated Multi-Year Budget'!$C$8:$V$8,'Updated Multi-Year Budget'!J47:AC47) -> 0 | L35: Interest Revenues Earned | N35: =LOOKUP($C$5,'Updated Multi-Year Budget'!$C$8:$V$8,'Updated Multi-Year Budget'!N47:AG47) -> 0
A36: ='Updated Multi-Year Budget'!A48 -> Total Tax Uncollected Tax Increment | C36: =LOOKUP($C$5,'Updated Multi-Year Budget'!$C$8:$V$8,'Updated Multi-Year Budget'!C48:V48) -> 0 | H36: Total Tax Uncollected and Paid | J36: =LOOKUP($C$5,'Updated Multi-Year Budget'!$C$8:$V$8,'Updated Multi-Year Budget'!J48:AC48) -> 0 | L36: Total Tax Uncollected and Paid | N36: =LOOKUP($C$5,'Updated Multi-Year Budget'!$C$8:$V$8,'Updated Multi-Year Budget'!N48:AG48) -> 0
A37: ='Updated Multi-Year Budget'!A49 -> Total Tax Increment Actually Collected and Paid | C37: =LOOKUP($C$5,'Updated Multi-Year Budget'!$C$8:$V$8,'Updated Multi-Year Budget'!C49:V49) -> 92734.037 | H37: Total Tax Increment Actually Collected and Paid | J37: ='Updated Multi-Year Budget'!D49 -> 115346.89 | L37: Total Tax Increment Actually Collected and Paid | N37: ='Updated Multi-Year Budget'!E49 -> 159404.14
A38: RDA Fund Balance | C38: =LOOKUP($C$5,'Updated Multi-Year Budget'!$C$8:$V$8,'Updated Multi-Year Budget'!C50:V50) -> 150000 | H38: RDA Fund Balance | J38: ='Updated Multi-Year Budget'!D50 -> 150000 | L38: RDA Fund Balance | N38: =LOOKUP($C$5,'Updated Multi-Year Budget'!$C$8:$V$8,'Updated Multi-Year Budget'!N50:AG50) -> 150000
A39: Total Sources of Revenue | C39: =LOOKUP($C$5,'Updated Multi-Year Budget'!$C$8:$V$8,'Updated Multi-Year Budget'!C51:V51) -> 242734.04 | H39: Total Sources of Revenue | J39: =SUM(J35:J38) -> 265346.89 | L39: Total Sources of Revenue | N39: =SUM(N37:N38) -> 309404.14
A41: EXPENDITURES | H41: EXPENDITURES | L41: EXPENDITURES
A42: PROJECT AREA BUDGET AND USE OF FUNDS | H42: PROJECT AREA BUDGET AND USE OF FUNDS | L42: PROJECT AREA BUDGET AND USE OF FUNDS
...

Sheet Acreage
B2: Tax Year | C2: 2018 | D2: 2019 | E2: 2020
B3: Payment Year | C3: 2019 | D3: 2020 | E3: 2021
B4: Developed | C4: 85 | D4: =C4+D26 -> 951.6 | E4: =D4+E26 -> 966.78
B5: Undeveloped | C5: 40 | D5: =D6-D4 -> 274.4 | E5: =E6-E4 -> 259.22
B6: Total Acres | C6: 125 | D6: =C6 -> 1226 | E6: =D6 -> 1226
B7: % Developed | C7: 0.68 | D7: =D4/D6 -> 0.77618271 | E7: =E4/E6 -> 0.78856444
B8: % Undeveloped | C8: 0.32 | D8: =D5/D6 -> 0.22381729 | E8: =E5/E6 -> 0.21143556
C9: 60
C10: 150
D14: 2019 | E14: 2020 | F14: =E14+1 -> 2021
B15: New Development | D15: 2020 | E15: 2021 | F15: =E15+1 -> 2022
D16: 5.5 | E16: =6.88+8.3 -> 15.18
D17: 72.1
B26: New Dev Total | D26: =SUM(D16:D25) -> 77.6 | E26: =SUM(E16:E25) -> 15.18 | F26: =SUM(F16:F25) -> 0 | G26: =SUM(G16:G25) -> 0 | H26: =SUM(H16:H25) -> 0 | I26: =SUM(I16:I25) -> 0 | J26: =SUM(J16:J25) -> 0
